2022-03-08 14:41:54,285 INFO    MainThread:12812 [internal.py:wandb_internal():89] W&B internal server running at pid: 12812, started at: 2022-03-08 14:41:54.274410
2022-03-08 14:41:54,288 INFO    WriterThread:12812 [datastore.py:open_for_write():77] open: C:\Users\Safwen\Desktop\Tensorborad\wandb\run-20220308_144151-1ig7iw7n\run-1ig7iw7n.wandb
2022-03-08 14:41:54,289 DEBUG   HandlerThread:12812 [handler.py:handle_request():131] handle_request: check_version
2022-03-08 14:41:54,298 DEBUG   SenderThread:12812 [sender.py:send():235] send: header
2022-03-08 14:41:54,298 DEBUG   SenderThread:12812 [sender.py:send_request():249] send_request: check_version
2022-03-08 14:41:54,732 DEBUG   SenderThread:12812 [sender.py:send():235] send: run
2022-03-08 14:41:55,057 ERROR   SenderThread:12812 [internal_api.py:execute():143] 403 response executing GraphQL.
2022-03-08 14:41:55,058 ERROR   SenderThread:12812 [internal_api.py:execute():144] {"errors":[{"message":"permission denied","path":["upsertBucket"],"extensions":{"code":"PERMISSION_ERROR"}}],"data":{"upsertBucket":null}}
2022-03-08 14:41:55,742 INFO    HandlerThread:12812 [handler.py:finish():739] shutting down handler
2022-03-08 14:41:55,742 INFO    WriterThread:12812 [datastore.py:close():281] close: C:\Users\Safwen\Desktop\Tensorborad\wandb\run-20220308_144151-1ig7iw7n\run-1ig7iw7n.wandb
2022-03-08 14:41:55,743 ERROR   MainThread:12812 [internal.py:wandb_internal():164] Thread SenderThread:
Traceback (most recent call last):
  File "C:\Users\Safwen\anaconda3\lib\site-packages\wandb\sdk\lib\retry.py", line 102, in __call__
    result = self._call_fn(*args, **kwargs)
  File "C:\Users\Safwen\anaconda3\lib\site-packages\wandb\sdk\internal\internal_api.py", line 146, in execute
    six.reraise(*sys.exc_info())
  File "C:\Users\Safwen\anaconda3\lib\site-packages\six.py", line 719, in reraise
    raise value
  File "C:\Users\Safwen\anaconda3\lib\site-packages\wandb\sdk\internal\internal_api.py", line 140, in execute
    return self.client.execute(*args, **kwargs)
  File "C:\Users\Safwen\anaconda3\lib\site-packages\wandb\vendor\gql-0.2.0\gql\client.py", line 52, in execute
    result = self._get_result(document, *args, **kwargs)
  File "C:\Users\Safwen\anaconda3\lib\site-packages\wandb\vendor\gql-0.2.0\gql\client.py", line 60, in _get_result
    return self.transport.execute(document, *args, **kwargs)
  File "C:\Users\Safwen\anaconda3\lib\site-packages\wandb\vendor\gql-0.2.0\gql\transport\requests.py", line 39, in execute
    request.raise_for_status()
  File "C:\Users\Safwen\anaconda3\lib\site-packages\requests\models.py", line 941, in raise_for_status
    raise HTTPError(http_error_msg, response=self)
requests.exceptions.HTTPError: 403 Client Error: Forbidden for url: https://api.wandb.ai/graphql

During handling of the above exception, another exception occurred:

Traceback (most recent call last):
  File "C:\Users\Safwen\anaconda3\lib\site-packages\wandb\apis\normalize.py", line 24, in wrapper
    return func(*args, **kwargs)
  File "C:\Users\Safwen\anaconda3\lib\site-packages\wandb\sdk\internal\internal_api.py", line 1296, in upsert_run
    response = self.gql(mutation, variable_values=variable_values, **kwargs)
  File "C:\Users\Safwen\anaconda3\lib\site-packages\wandb\sdk\lib\retry.py", line 118, in __call__
    if not check_retry_fn(e):
  File "C:\Users\Safwen\anaconda3\lib\site-packages\wandb\util.py", line 821, in no_retry_auth
    raise CommError("Permission denied, ask the project owner to grant you access")
wandb.errors.CommError: Permission denied, ask the project owner to grant you access

During handling of the above exception, another exception occurred:

Traceback (most recent call last):
  File "C:\Users\Safwen\anaconda3\lib\site-packages\wandb\sdk\internal\internal_util.py", line 54, in run
    self._run()
  File "C:\Users\Safwen\anaconda3\lib\site-packages\wandb\sdk\internal\internal_util.py", line 105, in _run
    self._process(record)
  File "C:\Users\Safwen\anaconda3\lib\site-packages\wandb\sdk\internal\internal.py", line 305, in _process
    self._sm.send(record)
  File "C:\Users\Safwen\anaconda3\lib\site-packages\wandb\sdk\internal\sender.py", line 237, in send
    send_handler(record)
  File "C:\Users\Safwen\anaconda3\lib\site-packages\wandb\sdk\internal\sender.py", line 692, in send_run
    self._init_run(run, config_value_dict)
  File "C:\Users\Safwen\anaconda3\lib\site-packages\wandb\sdk\internal\sender.py", line 716, in _init_run
    server_run, inserted = self._api.upsert_run(
  File "C:\Users\Safwen\anaconda3\lib\site-packages\wandb\apis\normalize.py", line 62, in wrapper
    six.reraise(CommError, CommError(message, err), sys.exc_info()[2])
  File "C:\Users\Safwen\anaconda3\lib\site-packages\six.py", line 718, in reraise
    raise value.with_traceback(tb)
  File "C:\Users\Safwen\anaconda3\lib\site-packages\wandb\apis\normalize.py", line 24, in wrapper
    return func(*args, **kwargs)
  File "C:\Users\Safwen\anaconda3\lib\site-packages\wandb\sdk\internal\internal_api.py", line 1296, in upsert_run
    response = self.gql(mutation, variable_values=variable_values, **kwargs)
  File "C:\Users\Safwen\anaconda3\lib\site-packages\wandb\sdk\lib\retry.py", line 118, in __call__
    if not check_retry_fn(e):
  File "C:\Users\Safwen\anaconda3\lib\site-packages\wandb\util.py", line 821, in no_retry_auth
    raise CommError("Permission denied, ask the project owner to grant you access")
wandb.errors.CommError: Permission denied, ask the project owner to grant you access
2022-03-08 14:41:57,977 INFO    MainThread:12812 [internal.py:handle_exit():79] Internal process exited
